<?xml version="1.0" ?>
<!-- =================================================================================== -->
<!-- |    This document was autogenerated by xacro from models/soccerbot.xacro         | -->
<!-- |    EDITING THIS FILE BY HAND IS NOT RECOMMENDED                                 | -->
<!-- =================================================================================== -->
<robot name="soccerbot">
  <material name="white">
    <color rgba="1.0 1.0 1.0 1.0"/>
  </material>
  <material name="black">
    <color rgba="0.0 0.0 0.0 1.0"/>
  </material>
  <material name="silver">
    <color rgba="0.7 0.7 0.7 1.0"/>
  </material>
  <material name="yellow">
    <color rgba="0.9 0.9 0.0 1.0"/>
  </material>
  <material name="red">
    <color rgba="0.7 0.0 0.0 1.0"/>
  </material>
  <material name="green">
    <color rgba="0.0 0.7 0.0 1.0"/>
  </material>
  <material name="blue">
    <color rgba="0.0 0.0 0.7 1.0"/>
  </material>
  <material name="purple">
    <color rgba="0.7 0.0 0.7 1.0"/>
  </material>
  <material name="cyan">
    <color rgba="0.0 0.7 0.7 1.0"/>
  </material>
  <link name="/torso">
    <inertial>
      <mass value="1.529"/>
      <origin rpy="0 0 0" xyz="0.0082498 -0.0017440 -0.0522479"/>
      <inertia ixx="4.323e-3" ixy="5.549e-6" ixz="3.960e-5" iyy="5.198e-3" iyz="-1.509e-5" izz="3.567e-3"/>
    </inertial>
    <collision name="collision">
      <origin rpy="0 0 0" xyz="0 0 0"/>
      <geometry>
        <mesh filename="../meshes/torso.dae" scale="1 1 1"/>
      </geometry>
    </collision>
    <visual name="visual">
      <origin rpy="0 0 0" xyz="0 0 0"/>
      <geometry>
        <mesh filename="../meshes/torso.dae" scale="1 1 1"/>
      </geometry>
      <material name="black"/>
    </visual>
  </link>
  <link name="/left_bicep">
    <inertial>
      <mass value="0.213e-3"/>
      <origin rpy="0  0  0" xyz="0.000 0.02579 -0.04955"/>
      <inertia ixx="2.824e-4" ixy="0.000" ixz="0.0" iyy="2.744e-4" iyz="1.165e-05" izz="2.433e-5"/>
    </inertial>
    <collision name="collision">
      <origin rpy="0  0  0" xyz="0 0.0025 0"/>
      <geometry>
        <mesh filename="../meshes/left_bicep.dae" scale="1 1 1"/>
      </geometry>
    </collision>
    <visual name="visual">
      <origin rpy="0  0  0" xyz="0  0  0"/>
      <geometry>
        <mesh filename="../meshes/left_bicep.dae" scale="1 1 1"/>
      </geometry>
      <material name="white"/>
    </visual>
  </link>
  <link name="/left_forearm">
    <inertial>
      <mass value="45.7e-3"/>
      <origin rpy="0  0  0" xyz="0 0.0245 -0.0546097"/>
      <inertia ixx="0.113e-3" ixy="0.000" ixz="1e-06" iyy="0.107e-3" iyz="0.0" izz="0.012e-3"/>
    </inertial>
    <collision name="collision">
      <origin rpy="0  0  0" xyz="-0.0055 0.005 0"/>
      <geometry>
        <mesh filename="../meshes/left_forearm.dae" scale="1 1 1"/>
      </geometry>
    </collision>
    <visual name="visual">
      <origin rpy="0  0  0" xyz="0  0  0"/>
      <geometry>
        <mesh filename="../meshes/left_forearm.dae" scale="1 1 1"/>
      </geometry>
      <material name="purple"/>
    </visual>
  </link>
  <joint name="left_arm_motor_0" type="revolute">
    <parent link="/torso"/>
    <child link="/left_bicep"/>
    <origin rpy="0 0 0" xyz="-0.0157 0.0725 0"/>
    <axis xyz="0 -1 0"/>
    <dynamics damping="0.01" friction="0.1"/>
    <limit effort="1.5" lower="-1.5707963267948966" upper="3.9269908169872414" velocity="1"/>
  </joint>
  <joint name="left_arm_motor_1" type="revolute">
    <parent link="/left_bicep"/>
    <child link="/left_forearm"/>
    <origin rpy="0 0 0" xyz="0 0 -0.10"/>
    <axis xyz="0 -1 0"/>
    <dynamics damping="0.01" friction="0.1"/>
    <limit effort="1.5" lower="0" upper="3.141592653589793" velocity="1"/>
  </joint>
  <link name="/right_bicep">
    <inertial>
      <mass value="0.213e-3"/>
      <origin rpy="0  0  0" xyz="0.000 -0.02579 -0.04955"/>
      <inertia ixx="2.824e-4" ixy="0.000" ixz="-0.0" iyy="2.744e-4" iyz="-1.165e-05" izz="2.433e-5"/>
    </inertial>
    <collision name="collision">
      <origin rpy="0  0  0" xyz="0 -0.0025 0"/>
      <geometry>
        <mesh filename="../meshes/right_bicep.dae" scale="1 1 1"/>
      </geometry>
    </collision>
    <visual name="visual">
      <origin rpy="0  0  0" xyz="0  0  0"/>
      <geometry>
        <mesh filename="../meshes/right_bicep.dae" scale="1 1 1"/>
      </geometry>
      <material name="white"/>
    </visual>
  </link>
  <link name="/right_forearm">
    <inertial>
      <mass value="45.7e-3"/>
      <origin rpy="0  0  0" xyz="0 -0.0245 -0.0546097"/>
      <inertia ixx="0.113e-3" ixy="0.000" ixz="-1e-06" iyy="0.107e-3" iyz="-0.0" izz="0.012e-3"/>
    </inertial>
    <collision name="collision">
      <origin rpy="0  0  0" xyz="-0.0055 -0.005 0"/>
      <geometry>
        <mesh filename="../meshes/right_forearm.dae" scale="1 1 1"/>
      </geometry>
    </collision>
    <visual name="visual">
      <origin rpy="0  0  0" xyz="0  0  0"/>
      <geometry>
        <mesh filename="../meshes/right_forearm.dae" scale="1 1 1"/>
      </geometry>
      <material name="purple"/>
    </visual>
  </link>
  <joint name="right_arm_motor_0" type="revolute">
    <parent link="/torso"/>
    <child link="/right_bicep"/>
    <origin rpy="0 0 0" xyz="-0.0157 -0.0725 0"/>
    <axis xyz="0 -1 0"/>
    <dynamics damping="0.01" friction="0.1"/>
    <limit effort="1.5" lower="-1.5707963267948966" upper="3.9269908169872414" velocity="1"/>
  </joint>
  <joint name="right_arm_motor_1" type="revolute">
    <parent link="/right_bicep"/>
    <child link="/right_forearm"/>
    <origin rpy="0 0 0" xyz="0 0 -0.10"/>
    <axis xyz="0 -1 0"/>
    <dynamics damping="0.01" friction="0.1"/>
    <limit effort="1.5" lower="0" upper="3.141592653589793" velocity="1"/>
  </joint>
  <link name="/left_hip_side">
    <inertial>
      <mass value="9.364e-3"/>
      <origin rpy="0  0  0" xyz="0.0003695 0.0000 0.01689"/>
      <inertia ixx="0.002e-3" ixy="0.000" ixz="0.000" iyy="0.005e-3" iyz="0.000" izz="0.004e-3"/>
    </inertial>
    <collision name="collision">
      <origin rpy="0  0  0" xyz="0 0.0 0.03"/>
        <geometry>
            <box size="0.0485 0.022 0.00005"/>
        </geometry>
    </collision>
    <visual name="visual">
      <origin rpy="0  0  0" xyz="0  0  0"/>
      <geometry>
        <mesh filename="../meshes/left_hip_side.dae" scale="1 1 1"/>
      </geometry>
      <material name="cyan"/>
    </visual>
  </link>
  <link name="/left_hip_front">
    <inertial>
      <mass value="153.186e-3"/>
      <origin rpy="0 0 0" xyz="-0.02093 0 -0.011313"/>
      <inertia ixx="0.041e-3" ixy="0.000" ixz="-0.002e-3" iyy="0.118e-3" iyz="0.000" izz="0.106e-3"/>
    </inertial>
    <collision name="collision">
      <origin rpy="0 0 0" xyz="-0.02187 0.0 -0.01332"/>
      <geometry>
        <box size="0.083747 0.04885 0.0506"/>
      </geometry>
    </collision>
    <visual name="visual">
      <origin rpy="0  0  0" xyz="0  0  0"/>
      <geometry>
        <mesh filename="../meshes/left_hip_front.dae" scale="1 1 1"/>
      </geometry>
      <material name="blue"/>
    </visual>
  </link>
  <link name="/left_thigh">
    <inertial>
      <mass value="21.438e-3"/>
      <origin rpy="0 0 0" xyz="0.0019422 0.0001419 -0.0469409"/>
      <inertia ixx="0.025e-3" ixy="2e-06" ixz="0.000" iyy="0.016e-3" iyz="0.000" izz="0.010e-3"/>
    </inertial>
    <collision name="collision">
      <origin rpy="0 0 0" xyz="0 0 -0.0445"/>
      <geometry>
        <box size="0.022 0.048 0.111"/>
      </geometry>
    </collision>
    <visual name="visual">
      <origin rpy="0  0  0" xyz="0  0  0"/>
      <geometry>
        <mesh filename="../meshes/left_thigh.dae" scale="1 1 1"/>
      </geometry>
      <material name="red"/>
    </visual>
  </link>
  <link name="/left_calve">
    <inertial>
      <mass value="86.547e-3"/>
      <origin rpy="0  0  0" xyz="0 -3.259e-07 -0.0150123e-3"/>
      <inertia ixx="0.054e-3" ixy="0.000" ixz="0.000" iyy="0.046e-3" iyz="-0.001e-3" izz="0.019e-3"/>
    </inertial>
    <collision name="collision">
      <origin rpy="0 0 0" xyz="0 0 -0.03385"/>
      <geometry>
        <box size="0.031883 0.048 0.105683"/>
      </geometry>
    </collision>
    <visual name="visual">
      <origin rpy="0 0 0" xyz="0 0 -0.0865"/>
      <geometry>
        <mesh filename="../meshes/left_calve.dae" scale="1 1 1"/>
      </geometry>
      <material name="yellow"/>
    </visual>
  </link>
  <link name="/left_ankle">
    <inertial>
      <mass value="153.186e-3"/>
      <origin rpy="0 0 0" xyz="-0.020939e-3 0.000 0.011313e-3"/>
      <inertia ixx="0.041e-3" ixy="0.000" ixz="0.002e-3" iyy="0.118e-3" iyz="0.000" izz="0.106e-3"/>
    </inertial>
    <collision name="collision">
      <origin rpy="0 0 0" xyz="-0.02014 0.0 0.01031"/>
      <geometry>
        <box size="0.090769 0.042 0.0506"/>
      </geometry>
    </collision>
    <visual name="visual">
      <origin rpy="0 0 0" xyz="0  0  0"/>
      <geometry>
        <mesh filename="../meshes/left_ankle.dae" scale="1 1 1"/>
      </geometry>
      <material name="purple"/>
    </visual>
  </link>
  <link name="/left_foot">
    <inertial>
      <mass value="23.216e-3"/>
      <origin rpy="0 0 0" xyz="-0.020939 0.0 0.011313"/>
      <inertia ixx="0.006e-3" ixy="0.000" ixz="0.000" iyy="0.018e-3" iyz="0.000" izz="0.022e-3"/>
    </inertial>
    <collision name="collision">
      <origin rpy="0 0 0" xyz="0.00225 0.00401 -0.0205 "/>
      <geometry>
        <box size="0.09 0.07 0.003"/>
      </geometry>
      <contact_coefficients mu="100.0"/>
    </collision>
    <visual name="visual">
      <origin rpy="0  0  0" xyz="0  0.00802  0"/>
      <geometry>
        <mesh filename="../meshes/left_foot.dae" scale="1 1 1"/>
      </geometry>
      <material name="green"/>
    </visual>
  </link>
  <link name="/left_foot_cleat_4">
    <inertial>
      <mass value="5e-3"/>
      <origin rpy="0 0 0" xyz="-0.020939 0.0 0.011313"/>
      <inertia ixx="0" ixy="0.000" ixz="0.000" iyy="0" iyz="0.000" izz="0"/>
    </inertial>
    <collision name="collision">
      <origin rpy="0 0 0" xyz="0.04225 0.034 -0.023"/>
      <geometry>
        <box size="0.01 0.01 0.002"/>
      </geometry>
      <contact_coefficients mu="100.0"/>
    </collision>
    <visual name="visual">
      <origin rpy="0 0 0" xyz="0.04225 0.034 -0.023"/>
      <geometry>
        <box size="0.01 0.01 0.002"/>
      </geometry>
      <material name="black"/>
    </visual>
  </link>
  <link name="/left_foot_cleat_5">
    <inertial>
      <mass value="5e-3"/>
      <origin rpy="0 0 0" xyz="-0.020939 0.0 0.011313"/>
      <inertia ixx="0" ixy="0.000" ixz="0.000" iyy="0" iyz="0.000" izz="0"/>
    </inertial>
    <collision name="collision">
      <origin rpy="0 0 0" xyz="0.04225 -0.026 -0.023"/>
      <geometry>
        <box size="0.01 0.01 0.002"/>
      </geometry>
      <contact_coefficients mu="100.0"/>
    </collision>
    <visual name="visual">
      <origin rpy="0 0 0" xyz="0.04225 -0.026 -0.023"/>
      <geometry>
        <box size="0.01 0.01 0.002"/>
      </geometry>
      <material name="red"/>
    </visual>
  </link>
  <link name="/left_foot_cleat_6">
    <inertial>
      <mass value="5e-3"/>
      <origin rpy="0 0 0" xyz="-0.020939 0.0 0.011313"/>
      <inertia ixx="0" ixy="0.000" ixz="0.000" iyy="0" iyz="0.000" izz="0"/>
    </inertial>
    <collision name="collision">
      <origin rpy="0 0 0" xyz="-0.03750 0.034 -0.023"/>
      <geometry>
        <box size="0.01 0.01 0.002"/>
      </geometry>
      <contact_coefficients mu="100.0"/>
    </collision>
    <visual name="visual">
      <origin rpy="0 0 0" xyz="-0.03750 0.034 -0.023"/>
      <geometry>
        <box size="0.01 0.01 0.002"/>
      </geometry>
      <material name="cyan"/>
    </visual>
  </link>
  <link name="/left_foot_cleat_7">
    <inertial>
      <mass value="5e-3"/>
      <origin rpy="0 0 0" xyz="-0.020939 0.0 0.011313"/>
      <inertia ixx="0" ixy="0.000" ixz="0.000" iyy="0" iyz="0.000" izz="0"/>
    </inertial>
    <collision name="collision">
      <origin rpy="0 0 0" xyz="-0.0375 -0.026 -0.023"/>
      <geometry>
        <box size="0.01 0.01 0.002"/>
      </geometry>
      <contact_coefficients mu="100.0"/>
    </collision>
    <visual name="visual">
      <origin rpy="0 0 0" xyz="-0.0375 -0.026 -0.023"/>
      <geometry>
        <box size="0.01 0.01 0.002"/>
      </geometry>
      <material name="blue"/>
    </visual>
  </link>
  <joint name="left_leg_motor_0" type="revolute">
    <parent link="/torso"/>
    <child link="/left_hip_side"/>
    <origin rpy="0 0 0" xyz="0.0135 0.035 -0.156"/>
    <axis xyz="0 0 -1"/>
    <dynamics damping="0.01" friction="0.1"/>
    <limit effort="2.5" lower="-1.309" upper="0.524" velocity="1"/>
  </joint>
  <joint name="left_leg_motor_1" type="revolute">
    <parent link="/left_hip_side"/>
    <child link="/left_hip_front"/>
    <origin rpy="0 0 0" xyz="0 0 0"/>
    <axis xyz="1 0 0"/>
    <dynamics damping="0.01" friction="0.1"/>
    <limit effort="2.5" lower="-0.7853981633974483" upper="1.5707963267948966" velocity="1"/>
  </joint>
  <joint name="left_leg_motor_2" type="revolute">
    <parent link="/left_hip_front"/>
    <child link="/left_thigh"/>
    <origin rpy="0 0 0" xyz="0 0 0"/>
    <axis xyz="0 -1 0"/>
    <dynamics damping="0.01" friction="0.1"/>
    <limit effort="2.5" lower="-0.7853981633974483" upper="2.356194490192345" velocity="1"/>
  </joint>
  <joint name="left_leg_motor_3" type="revolute">
    <parent link="/left_thigh"/>
    <child link="/left_calve"/>
    <origin rpy="0 0 0" xyz="0 0 -0.08900"/>
    <axis xyz="0 -1 0"/>
    <dynamics damping="0.01" friction="0.1"/>
    <limit effort="2.5" lower="-2.793" upper="0" velocity="1"/>
  </joint>
  <joint name="left_leg_motor_4" type="revolute">
    <parent link="/left_calve"/>
    <child link="/left_ankle"/>
    <origin rpy="0 0 0" xyz="0 0 -0.0865"/>
    <axis xyz="0 -1 0"/>
    <dynamics damping="0.01" friction="0.1"/>
    <limit effort="2.5" lower="-0.7853981633974483" upper="1.5707963267948966" velocity="1"/>
  </joint>
  <joint name="left_leg_motor_5" type="revolute">
    <parent link="/left_ankle"/>
    <child link="/left_foot"/>
    <origin rpy="0 0 0" xyz="0 0 0"/>
    <axis xyz="1 0 0"/>
    <dynamics damping="0.01" friction="0.1"/>
    <limit effort="2.5" lower="-0.7853981633974483" upper="0.7853981633974483" velocity="1"/>
  </joint>
  <joint name="/left_foot_cleat_4" type="fixed">
    <parent link="/left_foot"/>
    <child link="/left_foot_cleat_4"/>
    <origin rpy="0 0 0" xyz="0.0 0 0.0"/>
    <axis xyz="0 0 0"/>
  </joint>
  <joint name="/left_foot_cleat_5" type="fixed">
    <parent link="/left_foot"/>
    <child link="/left_foot_cleat_5"/>
    <origin rpy="0 0 0" xyz="0.0 0 0.0"/>
    <axis xyz="0 0 0"/>
  </joint>
  <joint name="/left_foot_cleat_6" type="fixed">
    <parent link="/left_foot"/>
    <child link="/left_foot_cleat_6"/>
    <origin rpy="0 0 0" xyz="0.0 0 0.0"/>
    <axis xyz="0 0 0"/>
  </joint>
  <joint name="/left_foot_cleat_7" type="fixed">
    <parent link="/left_foot"/>
    <child link="/left_foot_cleat_7"/>
    <origin rpy="0 0 0" xyz="0.0 0 0.0"/>
    <axis xyz="0 0 0"/>
  </joint>
  <link name="/right_hip_side">
    <inertial>
      <mass value="9.364e-3"/>
      <origin rpy="0  0  0" xyz="0.0003695 0.0000 0.01689"/>
      <inertia ixx="0.002e-3" ixy="0.000" ixz="0.000" iyy="0.005e-3" iyz="0.000" izz="0.004e-3"/>
    </inertial>
    <collision name="collision">
      <origin rpy="0  0  0" xyz="0 0 0.03"/>
        <geometry>
            <box size="0.0485 0.022 0.00005"/>
        </geometry>
    </collision>
    <visual name="visual">
      <origin rpy="0  0  0" xyz="0  0  0"/>
      <geometry>
        <mesh filename="../meshes/right_hip_side.dae" scale="1 1 1"/>
      </geometry>
      <material name="cyan"/>
    </visual>
  </link>
  <link name="/right_hip_front">
    <inertial>
      <mass value="153.186e-3"/>
      <origin rpy="0 0 0" xyz="-0.02093 0 -0.011313"/>
      <inertia ixx="0.041e-3" ixy="0.000" ixz="-0.002e-3" iyy="0.118e-3" iyz="0.000" izz="0.106e-3"/>
    </inertial>
    <collision name="collision">
      <origin rpy="0 0 0" xyz="-0.02187 0 -0.01332"/>
      <geometry>
        <box size="0.083747 0.04885 0.0506"/>
      </geometry>
    </collision>
    <visual name="visual">
      <origin rpy="0  0  0" xyz="0  0  0"/>
      <geometry>
        <mesh filename="../meshes/right_hip_front.dae" scale="1 1 1"/>
      </geometry>
      <material name="blue"/>
    </visual>
  </link>
  <link name="/right_thigh">
    <inertial>
      <mass value="21.438e-3"/>
      <origin rpy="0 0 0" xyz="0.0019422 -0.0001419 -0.0469409"/>
      <inertia ixx="0.025e-3" ixy="-2e-06" ixz="0.000" iyy="0.016e-3" iyz="0.000" izz="0.010e-3"/>
    </inertial>
    <collision name="collision">
      <origin rpy="0 0 0" xyz="0 0 -0.0445"/>
      <geometry>
        <box size="0.022 0.048 0.111"/>
      </geometry>
    </collision>
    <visual name="visual">
      <origin rpy="0  0  0" xyz="0  0  0"/>
      <geometry>
        <mesh filename="../meshes/right_thigh.dae" scale="1 1 1"/>
      </geometry>
      <material name="red"/>
    </visual>
  </link>
  <link name="/right_calve">
    <inertial>
      <mass value="86.547e-3"/>
      <origin rpy="0  0  0" xyz="0 3.259e-07 -0.0150123e-3"/>
      <inertia ixx="0.054e-3" ixy="0.000" ixz="0.000" iyy="0.046e-3" iyz="-0.001e-3" izz="0.019e-3"/>
    </inertial>
    <collision name="collision">
      <origin rpy="0 0 0" xyz="0 0 -0.03385"/>
      <geometry>
        <box size="0.031883 0.048 0.105683"/>
      </geometry>
    </collision>
    <visual name="visual">
      <origin rpy="0 0 0" xyz="0 0 -0.0865"/>
      <geometry>
        <mesh filename="../meshes/right_calve.dae" scale="1 1 1"/>
      </geometry>
      <material name="yellow"/>
    </visual>
  </link>
  <link name="/right_ankle">
    <inertial>
      <mass value="153.186e-3"/>
      <origin rpy="0 0 0" xyz="-0.020939e-3 0.000 0.011313e-3"/>
      <inertia ixx="0.041e-3" ixy="0.000" ixz="0.002e-3" iyy="0.118e-3" iyz="0.000" izz="0.106e-3"/>
    </inertial>
    <collision name="collision">
      <origin rpy="0 0 0" xyz="-0.02014 0 0.01031"/>
      <geometry>
        <box size="0.090769 0.042 0.0506"/>
      </geometry>
    </collision>
    <visual name="visual">
      <origin rpy="0 0 0" xyz="0  0  0"/>
      <geometry>
        <mesh filename="../meshes/right_ankle.dae" scale="1 1 1"/>
      </geometry>
      <material name="purple"/>
    </visual>
  </link>
  <link name="/right_foot">
    <inertial>
      <mass value="23.216e-3"/>
      <origin rpy="0 0 0" xyz="-0.020939 0.0 0.011313"/>
      <inertia ixx="0.006e-3" ixy="0.000" ixz="0.000" iyy="0.018e-3" iyz="0.000" izz="0.022e-3"/>
    </inertial>
    <collision name="collision">
      <origin rpy="0 0 0" xyz="0.00225 -0.00401 -0.0205 "/>
      <geometry>
        <box size="0.09 0.07 0.003"/>
      </geometry>
      <contact_coefficients mu="100.0"/>
    </collision>
    <visual name="visual">
      <origin rpy="0  0  0" xyz="0  -0.00802  0"/>
      <geometry>
        <mesh filename="../meshes/right_foot.dae" scale="1 1 1"/>
      </geometry>
      <material name="green"/>
    </visual>
  </link>
  <link name="/right_foot_cleat_0">
    <inertial>
      <mass value="5e-3"/>
      <origin rpy="0 0 0" xyz="-0.020939 0.0 0.011313"/>
      <inertia ixx="0" ixy="0.000" ixz="0.000" iyy="0" iyz="0.000" izz="0"/>
    </inertial>
    <collision name="collision">
      <origin rpy="0 0 0" xyz="0.04225 0.026 -0.023"/>
      <geometry>
        <box size="0.01 0.01 0.002"/>
      </geometry>
      <contact_coefficients mu="100.0"/>
    </collision>
    <visual name="visual">
      <origin rpy="0 0 0" xyz="0.04225 0.026 -0.023"/>
      <geometry>
        <box size="0.01 0.01 0.002"/>
      </geometry>
      <material name="black"/>
    </visual>
  </link>
  <link name="/right_foot_cleat_1">
    <inertial>
      <mass value="5e-3"/>
      <origin rpy="0 0 0" xyz="-0.020939 0.0 0.011313"/>
      <inertia ixx="0" ixy="0.000" ixz="0.000" iyy="0" iyz="0.000" izz="0"/>
    </inertial>
    <collision name="collision">
      <origin rpy="0 0 0" xyz="0.04225 -0.034 -0.023"/>
      <geometry>
        <box size="0.01 0.01 0.002"/>
      </geometry>
      <contact_coefficients mu="100.0"/>
    </collision>
    <visual name="visual">
      <origin rpy="0 0 0" xyz="0.04225 -0.034 -0.023"/>
      <geometry>
        <box size="0.01 0.01 0.002"/>
      </geometry>
      <material name="red"/>
    </visual>
  </link>
  <link name="/right_foot_cleat_2">
    <inertial>
      <mass value="5e-3"/>
      <origin rpy="0 0 0" xyz="-0.020939 0.0 0.011313"/>
      <inertia ixx="0" ixy="0.000" ixz="0.000" iyy="0" iyz="0.000" izz="0"/>
    </inertial>
    <collision name="collision">
      <origin rpy="0 0 0" xyz="-0.0375 0.026 -0.023"/>
      <geometry>
        <box size="0.01 0.01 0.002"/>
      </geometry>
      <contact_coefficients mu="100.0"/>
    </collision>
    <visual name="visual">
      <origin rpy="0 0 0" xyz="-0.0375 0.026 -0.023"/>
      <geometry>
        <box size="0.01 0.01 0.002"/>
      </geometry>
      <material name="cyan"/>
    </visual>
  </link>
  <link name="/right_foot_cleat_3">
    <inertial>
      <mass value="5e-3"/>
      <origin rpy="0 0 0" xyz="-0.020939 0.0 0.011313"/>
      <inertia ixx="0" ixy="0.000" ixz="0.000" iyy="0" iyz="0.000" izz="0"/>
    </inertial>
    <collision name="collision">
      <origin rpy="0 0 0" xyz="-0.0375 -0.034 -0.023"/>
      <geometry>
        <box size="0.01 0.01 0.002"/>
      </geometry>
      <contact_coefficients mu="100.0"/>
    </collision>
    <visual name="visual">
      <origin rpy="0 0 0" xyz="-0.0375 -0.034 -0.023"/>
      <geometry>
        <box size="0.01 0.01 0.002"/>
      </geometry>
      <material name="blue"/>
    </visual>
  </link>
  <joint name="right_leg_motor_0" type="revolute">
    <parent link="/torso"/>
    <child link="/right_hip_side"/>
    <origin rpy="0 0 0" xyz="0.0135 -0.035 -0.156"/>
    <axis xyz="0 0 1"/>
    <dynamics damping="0.01" friction="0.1"/>
    <limit effort="2.5" lower="-1.309" upper="0.524" velocity="1"/>
  </joint>
  <joint name="right_leg_motor_1" type="revolute">
    <parent link="/right_hip_side"/>
    <child link="/right_hip_front"/>
    <origin rpy="0 0 0" xyz="0 0 0"/>
    <axis xyz="-1 0 0"/>
    <dynamics damping="0.01" friction="0.1"/>
    <limit effort="2.5" lower="-0.7853981633974483" upper="1.5707963267948966" velocity="1"/>
  </joint>
  <joint name="right_leg_motor_2" type="revolute">
    <parent link="/right_hip_front"/>
    <child link="/right_thigh"/>
    <origin rpy="0 0 0" xyz="0 0 0"/>
    <axis xyz="0 -1 0"/>
    <dynamics damping="0.01" friction="0.1"/>
    <limit effort="2.5" lower="-0.7853981633974483" upper="2.356194490192345" velocity="1"/>
  </joint>
  <joint name="right_leg_motor_3" type="revolute">
    <parent link="/right_thigh"/>
    <child link="/right_calve"/>
    <origin rpy="0 0 0" xyz="0 0 -0.089"/>
    <axis xyz="0 -1 0"/>
    <dynamics damping="0.01" friction="0.1"/>
    <limit effort="2.5" lower="-2.793" upper="0" velocity="1"/>
  </joint>
  <joint name="right_leg_motor_4" type="revolute">
    <parent link="/right_calve"/>
    <child link="/right_ankle"/>
    <origin rpy="0 0 0" xyz="0 0 -0.0865"/>
    <axis xyz="0 -1 0"/>
    <dynamics damping="0.01" friction="0.1"/>
    <limit effort="2.5" lower="-0.7853981633974483" upper="1.5707963267948966" velocity="1"/>
  </joint>
  <joint name="right_leg_motor_5" type="revolute">
    <parent link="/right_ankle"/>
    <child link="/right_foot"/>
    <origin rpy="0 0 0" xyz="0 0 0"/>
    <axis xyz="-1 0 0"/>
    <dynamics damping="0.01" friction="0.1"/>
    <limit effort="2.5" lower="-0.7853981633974483" upper="0.7853981633974483" velocity="1"/>
  </joint>
  <joint name="right_foot_cleat_0" type="fixed">
    <parent link="/right_foot"/>
    <child link="/right_foot_cleat_0"/>
    <origin rpy="0 0 0" xyz="0.0 0 0.0"/>
    <axis xyz="0 0 0"/>
  </joint>
  <joint name="right_foot_cleat_1" type="fixed">
    <parent link="/right_foot"/>
    <child link="/right_foot_cleat_1"/>
    <origin rpy="0 0 0" xyz="0.0 0 0.0"/>
    <axis xyz="0 0 0"/>
  </joint>
  <joint name="right_foot_cleat_2" type="fixed">
    <parent link="/right_foot"/>
    <child link="/right_foot_cleat_2"/>
    <origin rpy="0 0 0" xyz="0.0 0 0.0"/>
    <axis xyz="0 0 0"/>
  </joint>
  <joint name="right_foot_cleat_3" type="fixed">
    <parent link="/right_foot"/>
    <child link="/right_foot_cleat_3"/>
    <origin rpy="0 0 0" xyz="0.0 0 0.0"/>
    <axis xyz="0 0 0"/>
  </joint>
  <link name="/neck">
    <inertial>
      <mass value="0.011294"/>
      <origin rpy="0  0  0" xyz="0 -0.0006476 0.0092453"/>
      <inertia ixx="5.489e-6" ixy="0" ixz="0" iyy="1.433e-6" iyz="0" izz="4.955e-6"/>
    </inertial>
    <collision name="collision">
      <origin rpy="0  0  0" xyz="0 0 0.0165"/>
      <geometry>
        <mesh filename="../meshes/neck.dae" scale="1 1 1"/>
      </geometry>
    </collision>
    <visual name="visual">
      <origin rpy="0  0  0" xyz="0  0  0"/>
      <geometry>
        <mesh filename="../meshes/neck.dae" scale="1 1 1"/>
      </geometry>
      <material name="silver"/>
    </visual>
  </link>
  <link name="/head">
    <inertial>
      <mass value="0.282"/>
      <origin rpy="0  0  0" xyz="0.0237166 0.0018096 0.0255966"/>
      <inertia ixx="2.06e-4" ixy="1.06e-6" ixz="-5.73e-5" iyy="2.057e-4" iyz="2.534e-6" izz="1.603e-4"/>
    </inertial>
    <collision name="collision">
      <origin rpy="0  0  0" xyz="-0.013 0 0.025"/>
      <geometry>
        <mesh filename="../meshes/head.dae" scale="1 1 1"/>
      </geometry>
    </collision>
    <visual name="visual">
      <origin rpy="0  0  0" xyz="0  0  0"/>
      <geometry>
        <mesh filename="../meshes/head.dae" scale="1 1 1"/>
      </geometry>
      <material name="silver"/>
    </visual>
  </link>
  <joint name="head_motor_0" type="revolute">
    <parent link="/torso"/>
    <child link="/neck"/>
    <origin rpy="0 0 0" xyz="0.024 0 0.05875"/>
    <axis xyz="0 0 1"/>
    <dynamics damping="0.01" friction="0.1"/>
    <limit effort="1.5" lower="-1.5707963267948966" upper="1.5707963267948966" velocity="1"/>
  </joint>
  <joint name="head_motor_1" type="revolute">
    <parent link="/neck"/>
    <child link="/head"/>
    <origin rpy="0 0 0" xyz="0 0 0.024"/>
    <axis xyz="0 1 0"/>
    <dynamics damping="0.01" friction="0.1"/>
    <limit effort="1.5" lower="-2.356194490192345" upper="2.356194490192345" velocity="1"/>
  </joint>
  <link name="/imu_link">
    <inertial>
      <mass value="0.01"/>
      <origin rpy="0  0  0" xyz="0 0 0"/>
      <inertia ixx="1e-9" ixy="0" ixz="0" iyy="1e-9" iyz="0" izz="1e-9"/>
    </inertial>
  </link>
  <joint name="/torso_imu" type="fixed">
    <parent link="/torso"/>
    <child link="/imu_link"/>
    <origin rpy="0 0 0" xyz="0.0 0 0.000"/>
    <axis xyz="0 0 0"/>
  </joint>
  <link name="/camera">
    <inertial>
      <mass value="0.01"/>
      <origin rpy="0  0  0" xyz="0 0 0"/>
      <inertia ixx="1e-9" ixy="0" ixz="0" iyy="1e-9" iyz="0" izz="1e-9"/>
    </inertial>
  </link>
  <joint name="/head_camera" type="fixed">
    <parent link="/head"/>
    <child link="/camera"/>
    <origin rpy="0 0 0" xyz="0.015 0.00145 0.04740"/>
    <axis xyz="0  0  0"/>
    <dynamics damping="0.01" friction="0.1"/>
    <limit effort="0" lower="0" upper="0" velocity="0"/>
  </joint>
</robot>
